Workbook

Sheet README
B2: Meterbook — Plan, Test & Reliability Tracker
B3: Meterbook: Usage-based billing and double-entry ledger for SaaS companies. Two tracks: the platform baseline every SaaS needs, then the product. Every task, test, metric, load run and chaos experiment is tracked here as evidence of reliability, not just functionality.
B5: SETTINGS
B6: Project start date | C6: 46328
B8: TRACKS
B9: Platform | C9: Platform baseline: auth, tenancy, API keys, RBAC, audit, quotas, CI/CD, infra
B10: Product | C10: Meterbook product: Usage-based billing and double-entry ledger for SaaS companies
B15: HOW TO USE
B16: 1. Plan | C16: Work top-down by Week. Set Status (dropdown) and % Complete as you go. Done forces 100%. Paste the PR / commit link in Evidence.
B17: 2. Test_Catalog | C17: Reference of 40+ test types (black/white/grey box), what each proves, when it runs in CI, tools per language and the pass gate.
B18: 3. Test_Cases | C18: Concrete test cases per project. After each run set Status, Last Run date, Actual Result and an Evidence link (CI run, report).
B19: 4. Metrics_SLOs | C19: Targets are pre-filled. Type the measured value; Result computes PASS/FAIL against the target automatically.
B20: 5. Load_Stress_Runs | C20: Planned load / stress / spike / soak / scalability / volume runs. Enter results from k6/Gatling/Locust; Result checks throughput, p99 and error rate against the SLO columns.
B21: 6. Chaos_Resilience | C21: Fault-injection experiments. Enter observed behaviour, recovery time and data loss; Result checks against the RTO target.
B22: 7. Coverage | C22: Line / branch / mutation scores per module, checked against targets.
B23: 8. Defects | C23: Every bug found by a test: severity, test ID, root cause, fix PR, and whether a regression test was added.
B24: 9. Weekly_Log | C24: One row per week: planned vs done (auto), hours, blockers, learnings, demo link.
B25: 10. Dashboard | C25: Auto-calculated progress, test pass rates, SLO status and a Release Gate per track. Show this sheet to recruiters.
B27: LEGEND
B28: Blue text, yellow fill | C28: Input cell — you edit these.
B29: Black text | C29: Formula or pre-filled plan content — leave formulas alone.
B30: Grey italic row | C30: EXAMPLE row showing the expected format. Excluded from every Dashboard total. Delete or keep.
B31: Green / Red / Grey | C31: PASS / FAIL / NOT RUN or PENDING result highlighting.
B33: CONVENTIONS
B34: Percentages | C34: Enter as fractions or with %: 0.85 or 85% (not 85).
B35: Latency | C35: Milliseconds unless the Unit column says otherwise.
B36: Error rate | C36: Fraction of requests: 0.1% = 0.001.
B37: Evidence | C37: Every PASS should link to proof: CI run, Grafana snapshot, k6 HTML report, Chaos Mesh log. That link is what convinces a reviewer.
B38: Targets | C38: Targets are engineering goals chosen for these designs, not published industry standards. Tighten them once you have a baseline.

Sheet Dashboard
A1: Meterbook Dashboard
A2: All figures calculate from the other sheets. EXAMPLE rows are excluded.
A4: Measure | B4: Platform | C4: Product | D4: TOTAL
A5: Project | B5: Platform baseline: auth, tenancy, API keys, RBAC, audit, quotas, CI/CD, infra | C5: Meterbook product: Usage-based billing and double-entry ledger for SaaS companies
A6: DELIVERY PROGRESS
A7: Tasks | B7: =COUNTIF(Plan!$B$2:$B$600,B$4) | C7: =COUNTIF(Plan!$B$2:$B$600,C$4) | D7: =SUM(B7:C7)
A8: Done | B8: =COUNTIFS(Plan!$B$2:$B$600,B$4,Plan!$K$2:$K$600,"Done") | C8: =COUNTIFS(Plan!$B$2:$B$600,C$4,Plan!$K$2:$K$600,"Done") | D8: =SUM(B8:C8)
A9: In Progress | B9: =COUNTIFS(Plan!$B$2:$B$600,B$4,Plan!$K$2:$K$600,"In Progress") | C9: =COUNTIFS(Plan!$B$2:$B$600,C$4,Plan!$K$2:$K$600,"In Progress") | D9: =SUM(B9:C9)
A10: Blocked | B10: =COUNTIFS(Plan!$B$2:$B$600,B$4,Plan!$K$2:$K$600,"Blocked") | C10: =COUNTIFS(Plan!$B$2:$B$600,C$4,Plan!$K$2:$K$600,"Blocked") | D10: =SUM(B10:C10)
A11: Overdue | B11: =COUNTIFS(Plan!$B$2:$B$600,B$4,Plan!$P$2:$P$600,"OVERDUE") | C11: =COUNTIFS(Plan!$B$2:$B$600,C$4,Plan!$P$2:$P$600,"OVERDUE") | D11: =SUM(B11:C11)
A12: Est. Hours | B12: =SUMIF(Plan!$B$2:$B$600,B$4,Plan!$G$2:$G$600) | C12: =SUMIF(Plan!$B$2:$B$600,C$4,Plan!$G$2:$G$600) | D12: =SUM(B12:C12)
A13: Hours Earned | B13: =SUMPRODUCT((Plan!$B$2:$B$600=B$4)*Plan!$G$2:$G$600*Plan!$M$2:$M$600) | C13: =SUMPRODUCT((Plan!$B$2:$B$600=C$4)*Plan!$G$2:$G$600*Plan!$M$2:$M$600) | D13: =SUM(B13:C13)
A14: % Complete (hours-weighted) | B14: =IFERROR(B13/B12,0) | C14: =IFERROR(C13/C12,0) | D14: =IFERROR(D13/D12,0)
A16: TESTING
A17: Test Cases | B17: =COUNTIF(Test_Cases!$B$2:$B$600,B$4) | C17: =COUNTIF(Test_Cases!$B$2:$B$600,C$4) | D17: =SUM(B17:C17)
A18: Passed | B18: =COUNTIFS(Test_Cases!$B$2:$B$600,B$4,Test_Cases!$K$2:$K$600,"Pass") | C18: =COUNTIFS(Test_Cases!$B$2:$B$600,C$4,Test_Cases!$K$2:$K$600,"Pass") | D18: =SUM(B18:C18)
A19: Failed | B19: =COUNTIFS(Test_Cases!$B$2:$B$600,B$4,Test_Cases!$K$2:$K$600,"Fail") | C19: =COUNTIFS(Test_Cases!$B$2:$B$600,C$4,Test_Cases!$K$2:$K$600,"Fail") | D19: =SUM(B19:C19)
A20: Blocked | B20: =COUNTIFS(Test_Cases!$B$2:$B$600,B$4,Test_Cases!$K$2:$K$600,"Blocked") | C20: =COUNTIFS(Test_Cases!$B$2:$B$600,C$4,Test_Cases!$K$2:$K$600,"Blocked") | D20: =SUM(B20:C20)
A21: Not Run | B21: =COUNTIFS(Test_Cases!$B$2:$B$600,B$4,Test_Cases!$K$2:$K$600,"Not Run") | C21: =COUNTIFS(Test_Cases!$B$2:$B$600,C$4,Test_Cases!$K$2:$K$600,"Not Run") | D21: =SUM(B21:C21)
A22: Execution % | B22: =IFERROR((B17-B21)/B17,0) | C22: =IFERROR((C17-C21)/C17,0) | D22: =IFERROR((D17-D21)/D17,0)
A23: Pass Rate (of executed) | B23: =IFERROR(B18/(B18+B19),0) | C23: =IFERROR(C18/(C18+C19),0) | D23: =IFERROR(D18/(D18+D19),0)
A24: Automation % | B24: =IFERROR(COUNTIFS(Test_Cases!$B$2:$B$600,B$4,Test_Cases!$J$2:$J$600,"Y")/COUNTIF(Test_Cases!$B$2:$B$600,B$4),0) | C24: =IFERROR(COUNTIFS(Test_Cases!$B$2:$B$600,C$4,Test_Cases!$J$2:$J$600,"Y")/COUNTIF(Test_Cases!$B$2:$B$600,C$4),0) | D24: =IFERROR((COUNTIF(Test_Cases!$J$2:$J$600,"Y")-COUNTIFS(Test_Cases!$B$2:$B$600,"EXAMPLE",Test_Cases!$J$2:$J$600,"Y"))/D17,0)
A26: SLOs & RELIABILITY
A27: Metrics | B27: =COUNTIF(Metrics_SLOs!$B$2:$B$600,B$4) | C27: =COUNTIF(Metrics_SLOs!$B$2:$B$600,C$4) | D27: =SUM(B27:C27)
A28: Metrics PASS | B28: =COUNTIFS(Metrics_SLOs!$B$2:$B$600,B$4,Metrics_SLOs!$I$2:$I$600,"PASS") | C28: =COUNTIFS(Metrics_SLOs!$B$2:$B$600,C$4,Metrics_SLOs!$I$2:$I$600,"PASS") | D28: =SUM(B28:C28)
A29: Metrics FAIL | B29: =COUNTIFS(Metrics_SLOs!$B$2:$B$600,B$4,Metrics_SLOs!$I$2:$I$600,"FAIL") | C29: =COUNTIFS(Metrics_SLOs!$B$2:$B$600,C$4,Metrics_SLOs!$I$2:$I$600,"FAIL") | D29: =SUM(B29:C29)
A30: Metrics Pending | B30: =COUNTIFS(Metrics_SLOs!$B$2:$B$600,B$4,Metrics_SLOs!$I$2:$I$600,"PENDING") | C30: =COUNTIFS(Metrics_SLOs!$B$2:$B$600,C$4,Metrics_SLOs!$I$2:$I$600,"PENDING") | D30: =SUM(B30:C30)
A31: Load Runs | B31: =COUNTIF(Load_Stress_Runs!$B$2:$B$600,B$4) | C31: =COUNTIF(Load_Stress_Runs!$B$2:$B$600,C$4) | D31: =SUM(B31:C31)
A32: Load Runs PASS | B32: =COUNTIFS(Load_Stress_Runs!$B$2:$B$600,B$4,Load_Stress_Runs!$T$2:$T$600,"PASS") | C32: =COUNTIFS(Load_Stress_Runs!$B$2:$B$600,C$4,Load_Stress_Runs!$T$2:$T$600,"PASS") | D32: =SUM(B32:C32)
A33: Chaos Experiments | B33: =COUNTIF(Chaos_Resilience!$B$2:$B$600,B$4) | C33: =COUNTIF(Chaos_Resilience!$B$2:$B$600,C$4) | D33: =SUM(B33:C33)
A34: Chaos PASS | B34: =COUNTIFS(Chaos_Resilience!$B$2:$B$600,B$4,Chaos_Resilience!$M$2:$M$600,"PASS") | C34: =COUNTIFS(Chaos_Resilience!$B$2:$B$600,C$4,Chaos_Resilience!$M$2:$M$600,"PASS") | D34: =SUM(B34:C34)
A35: Coverage Modules PASS | B35: =COUNTIFS(Coverage!$A$2:$A$600,B$4,Coverage!$K$2:$K$600,"PASS")&" / "&COUNTIF(Coverage!$A$2:$A$600,B$4) | C35: =COUNTIFS(Coverage!$A$2:$A$600,C$4,Coverage!$K$2:$K$600,"PASS")&" / "&COUNTIF(Coverage!$A$2:$A$600,C$4) | D35: =(COUNTIF(Coverage!$K$2:$K$600,"PASS")-COUNTIFS(Coverage!$A$2:$A$600,"EXAMPLE",Coverage!$K$2:$K$600,"PASS"))&" / "&(COUNTA(Coverage!$A$2:$A$600)-COUNTIF(Coverage!$A$2:$A$600,"EXAMPLE"))
A37: QUALITY
A38: Open Defects | B38: =COUNTIFS(Defects!$B$2:$B$600,B$4,Defects!$F$2:$F$600,"Open")+COUNTIFS(Defects!$B$2:$B$600,B$4,Defects!$F$2:$F$600,"In Progress") | C38: =COUNTIFS(Defects!$B$2:$B$600,C$4,Defects!$F$2:$F$600,"Open")+COUNTIFS(Defects!$B$2:$B$600,C$4,Defects!$F$2:$F$600,"In Progress") | D38: =SUM(B38:C38)
A39: Open S1/S2 Defects | B39: =COUNTIFS(Defects!$B$2:$B$600,B$4,Defects!$F$2:$F$600,"Open",Defects!$D$2:$D$600,"S1-Critical")+COUNTIFS(Defects!$B$2:$B$600,B$4,Defects!$F$2:$F$600,"In Progress",Defects!$D$2:$D$600,"S1-Critical")+COUNTIFS(Defects!$B$2:$B$600,B$4,Defects!$F$2:$F$600,"Open",Defects!$D$2:$D$600,"S2-High")+COUNTIFS(Defects!$B$2:$B$600,B$4,Defects!$F$2:$F$600,"In Progress",Defects!$D$2:$D$600,"S2-High") | C39: =COUNTIFS(Defects!$B$2:$B$600,C$4,Defects!$F$2:$F$600,"Open",Defects!$D$2:$D$600,"S1-Critical")+COUNTIFS(Defects!$B$2:$B$600,C$4,Defects!$F$2:$F$600,"In Progress",Defects!$D$2:$D$600,"S1-Critical")+COUNTIFS(Defects!$B$2:$B$600,C$4,Defects!$F$2:$F$600,"Open",Defects!$D$2:$D$600,"S2-High")+COUNTIFS(Defects!$B$2:$B$600,C$4,Defects!$F$2:$F$600,"In Progress",Defects!$D$2:$D$600,"S2-High") | D39: =SUM(B39:C39)
A40: RELEASE GATE | B40: =IF(AND(B14>=1,B19=0,B21=0,B20=0,B29=0,B30=0,B32=B31,B34=B33,B39=0),"READY TO SHIP","NOT READY") | C40: =IF(AND(C14>=1,C19=0,C21=0,C20=0,C29=0,C30=0,C32=C31,C34=C33,C39=0),"READY TO SHIP","NOT READY") | D40: =IF(COUNTIF(B40:C40,"READY TO SHIP")=2,"ALL READY",COUNTIF(B40:C40,"READY TO SHIP")&" of 2 ready")
A42: Release Gate = READY TO SHIP only when: all tasks done, every test case run with 0 failures/blocked, every metric measured and passing, every load run and chaos experiment passing, and 0 open S1/S2 defects.
A44: TEST TYPE COVERAGE (cases per type, both tracks)
A45: Test Type | B45: Box | C45: Cases | D45: Passed | E45: Failed | F45: Not Run
A46: Unit | B46: =INDEX(Test_Catalog!$C$2:$C$48,MATCH(A46,Test_Catalog!$A$2:$A$48,0)) | C46: =COUNTIF(Test_Cases!$C$2:$C$600,A46)-COUNTIFS(Test_Cases!$C$2:$C$600,A46,Test_Cases!$B$2:$B$600,"EXAMPLE") | D46: =COUNTIFS(Test_Cases!$C$2:$C$600,A46,Test_Cases!$K$2:$K$600,"Pass")-COUNTIFS(Test_Cases!$C$2:$C$600,A46,Test_Cases!$K$2:$K$600,"Pass",Test_Cases!$B$2:$B$600,"EXAMPLE") | E46: =COUNTIFS(Test_Cases!$C$2:$C$600,A46,Test_Cases!$K$2:$K$600,"Fail")-COUNTIFS(Test_Cases!$C$2:$C$600,A46,Test_Cases!$K$2:$K$600,"Fail",Test_Cases!$B$2:$B$600,"EXAMPLE") | F46: =COUNTIFS(Test_Cases!$C$2:$C$600,A46,Test_Cases!$K$2:$K$600,"Not Run")-COUNTIFS(Test_Cases!$C$2:$C$600,A46,Test_Cases!$K$2:$K$600,"Not Run",Test_Cases!$B$2:$B$600,"EXAMPLE")
...

Sheet Plan
A1: Task ID | B1: Track | C1: Phase | D1: Task | E1: Definition of Done | F1: Priority | G1: Est. Hours | H1: Week # | I1: Planned Start | J1: Planned End | K1: Status | L1: % Complete (input) | M1: Effective % | N1: Actual Hours | O1: Done Date | P1: Schedule Flag | Q1: Evidence / PR Link | R1: Notes
A2: EX-001 | B2: EXAMPLE | C2: Core | D2: Example: idempotency middleware | E2: Duplicate POST returns stored response | F2: P0 | G2: 8 | I2: =IF(H2="","",README!$C$6+(H2-1)*7) | J2: =IF(H2="","",README!$C$6+(H2-1)*7+4) | K2: Done | L2: 1 | M2: =IF(K2="Done",1,IF(L2="",0,MIN(1,L2))) | N2: 9 | O2: 46332 | P2: =IF(K2="Done",IF(O2="","Done",IF(J2="","Done",IF(O2<=J2,"On time","Late"))),IF(K2="Blocked","BLOCKED",IF(I2="","",IF(TODAY()>J2,"OVERDUE",IF(TODAY()>=I2,"Active","Upcoming"))))) | Q2: https://github.com/you/repo/pull/42 | R2: Example row — format only
A3: MB-T01 | B3: Platform | C3: Design | D3: Repo layout, coding standards, ADR template, design-doc template | E3: Repo created; ADR-000 merged; templates in /docs | F3: P1 | G3: 6 | H3: 1 | I3: =IF(H3="","",README!$C$6+(H3-1)*7) | J3: =IF(H3="","",README!$C$6+(H3-1)*7+4) | K3: Done | L3: 1 | M3: =IF(K3="Done",1,IF(L3="",0,MIN(1,L3))) | O3: 46318 | P3: =IF(K3="Done",IF(O3="","Done",IF(J3="","Done",IF(O3<=J3,"On time","Late"))),IF(K3="Blocked","BLOCKED",IF(I3="","",IF(TODAY()>J3,"OVERDUE",IF(TODAY()>=I3,"Active","Upcoming"))))) | Q3: commit 19024d4 (branch foundation) | R3: Engineering rules, README, CONTRIBUTING, ADR-0000/0001, design + runbook templates, coding/testing/API/git standards
A4: MB-T02 | B4: Platform | C4: Design | D4: SLO document template and error-budget policy | E4: SLO template approved; policy says what happens when budget is spent | F4: P1 | G4: 4 | H4: 1 | I4: =IF(H4="","",README!$C$6+(H4-1)*7) | J4: =IF(H4="","",README!$C$6+(H4-1)*7+4) | K4: Done | L4: 1 | M4: =IF(K4="Done",1,IF(L4="",0,MIN(1,L4))) | O4: 46318 | P4: =IF(K4="Done",IF(O4="","Done",IF(J4="","Done",IF(O4<=J4,"On time","Late"))),IF(K4="Blocked","BLOCKED",IF(I4="","",IF(TODAY()>J4,"OVERDUE",IF(TODAY()>=I4,"Active","Upcoming"))))) | Q4: commit 19024d4 (branch foundation) | R4: docs/slo/template.md (burn-rate alerting) + docs/slo/error-budget-policy.md
A5: MB-T03 | B5: Platform | C5: Infra | D5: Terraform AWS baseline: VPC, EKS, RDS, S3, IAM, remote state with locking | E5: terraform plan/apply green from CI; state in S3 with native locking (ADR-0002) | F5: P0 | G5: 16 | H5: 1 | I5: =IF(H5="","",README!$C$6+(H5-1)*7) | J5: =IF(H5="","",README!$C$6+(H5-1)*7+4) | K5: In Progress | L5: 0.85 | M5: =IF(K5="Done",1,IF(L5="",0,MIN(1,L5))) | P5: =IF(K5="Done",IF(O5="","Done",IF(J5="","Done",IF(O5<=J5,"On time","Late"))),IF(K5="Blocked","BLOCKED",IF(I5="","",IF(TODAY()>J5,"OVERDUE",IF(TODAY()>=I5,"Active","Upcoming"))))) | Q5: https://github.com/mhrj7/meterbook/pull/7 | R5: In AWS (eu-north-1): GitHub OIDC provider and meterbook-terraform-apply role created; trust fixed to GitHub's immutable OIDC subjects after the first bootstrap run was rejected. GitHub environments dev/production limited to main. Stack merged to main (PRs #1-#6). Remaining: bootstrap run green (state bucket, plan role), then dev apply-verify-destroy once AWS finishes verifying the new account.
A6: MB-T04 | B6: Platform | C6: Infra | D6: Secrets management: Vault or AWS Secrets Manager + External Secrets Operator | E6: No secrets in git (gitleaks passes); pods read secrets at runtime | F6: P0 | G6: 6 | H6: 2 | I6: =IF(H6="","",README!$C$6+(H6-1)*7) | J6: =IF(H6="","",README!$C$6+(H6-1)*7+4) | K6: In Progress | L6: 0.9 | M6: =IF(K6="Done",1,IF(L6="",0,MIN(1,L6))) | P6: =IF(K6="Done",IF(O6="","Done",IF(J6="","Done",IF(O6<=J6,"On time","Late"))),IF(K6="Blocked","BLOCKED",IF(I6="","",IF(TODAY()>J6,"OVERDUE",IF(TODAY()>=I6,"Active","Upcoming"))))) | Q6: https://github.com/mhrj7/meterbook/actions/runs/39912053895 | R6: Green CI incl. kind end-to-end (4/4: delivery, runtime read by a pod, rotation in 3s, namespace isolation) after fixing a false-green CI step and a moto crash. Remaining: verify on real AWS (secrets, ESO role, Pod Identity) once the AWS account finishes verification and dev is applied.
A7: MB-T05 | B7: Platform | C7: CI/CD | D7: GitHub Actions: lint, test, build, SBOM (Syft), image scan (Trivy), cosign signing | E7: Pipeline < 10 min; fails on critical CVE | F7: P0 | G7: 12 | H7: 2 | I7: =IF(H7="","",README!$C$6+(H7-1)*7) | J7: =IF(H7="","",README!$C$6+(H7-1)*7+4) | K7: In Progress | L7: 0.85 | M7: =IF(K7="Done",1,IF(L7="",0,MIN(1,L7))) | P7: =IF(K7="Done",IF(O7="","Done",IF(J7="","Done",IF(O7<=J7,"On time","Late"))),IF(K7="Blocked","BLOCKED",IF(I7="","",IF(TODAY()>J7,"OVERDUE",IF(TODAY()>=I7,"Active","Upcoming"))))) | Q7: https://github.com/mhrj7/meterbook/actions/runs/39905115436 | R7: Green CI run on PR #3: 3.3 min wall clock (Terraform job 3.0 min). Done: ci.yml (Terraform fmt/validate/test/tflint/trivy, Gitleaks, actionlint, single ci check), reusable container.yml (Trivy CRITICAL gate, SBOM, cosign), Terraform plan/apply via OIDC, SHA-pinned actions, Dependabot, ADR-0003. Remaining: CRITICAL-CVE gate exercised by the first service image (MB-T07).
A8: MB-T06 | B8: Platform | C8: CI/CD | D8: Helm chart library + ArgoCD GitOps (dev / staging / prod) | E8: Merge to main auto-syncs staging; prod via promotion PR | F8: P0 | G8: 12 | H8: 2 | I8: =IF(H8="","",README!$C$6+(H8-1)*7) | J8: =IF(H8="","",README!$C$6+(H8-1)*7+4) | K8: Not Started | M8: =IF(K8="Done",1,IF(L8="",0,MIN(1,L8))) | P8: =IF(K8="Done",IF(O8="","Done",IF(J8="","Done",IF(O8<=J8,"On time","Late"))),IF(K8="Blocked","BLOCKED",IF(I8="","",IF(TODAY()>J8,"OVERDUE",IF(TODAY()>=I8,"Active","Upcoming")))))
A9: MB-T07 | B9: Platform | C9: Identity | D9: OIDC login (Keycloak/Zitadel), SAML SSO, SCIM provisioning | E9: SSO e2e test passes with a test IdP | F9: P0 | G9: 20 | H9: 3 | I9: =IF(H9="","",README!$C$6+(H9-1)*7) | J9: =IF(H9="","",README!$C$6+(H9-1)*7+4) | K9: Not Started | M9: =IF(K9="Done",1,IF(L9="",0,MIN(1,L9))) | P9: =IF(K9="Done",IF(O9="","Done",IF(J9="","Done",IF(O9<=J9,"On time","Late"))),IF(K9="Blocked","BLOCKED",IF(I9="","",IF(TODAY()>J9,"OVERDUE",IF(TODAY()>=I9,"Active","Upcoming")))))
A10: MB-T08 | B10: Platform | C10: Tenancy | D10: Tenant model org > project > env; Postgres row-level security | E10: Cross-tenant access test fails closed | F10: P0 | G10: 12 | H10: 3 | I10: =IF(H10="","",README!$C$6+(H10-1)*7) | J10: =IF(H10="","",README!$C$6+(H10-1)*7+4) | K10: Not Started | M10: =IF(K10="Done",1,IF(L10="",0,MIN(1,L10))) | P10: =IF(K10="Done",IF(O10="","Done",IF(J10="","Done",IF(O10<=J10,"On time","Late"))),IF(K10="Blocked","BLOCKED",IF(I10="","",IF(TODAY()>J10,"OVERDUE",IF(TODAY()>=I10,"Active","Upcoming")))))
A11: MB-T09 | B11: Platform | C11: Security | D11: Scoped, hashed API keys with rotation and revocation | E11: Revoked key rejected within 60 s | F11: P0 | G11: 8 | H11: 3 | I11: =IF(H11="","",README!$C$6+(H11-1)*7) | J11: =IF(H11="","",README!$C$6+(H11-1)*7+4) | K11: Not Started | M11: =IF(K11="Done",1,IF(L11="",0,MIN(1,L11))) | P11: =IF(K11="Done",IF(O11="","Done",IF(J11="","Done",IF(O11<=J11,"On time","Late"))),IF(K11="Blocked","BLOCKED",IF(I11="","",IF(TODAY()>J11,"OVERDUE",IF(TODAY()>=I11,"Active","Upcoming")))))
A12: MB-T10 | B12: Platform | C12: Security | D12: Service mesh mTLS (Linkerd or Istio) | E12: Plaintext pod-to-pod traffic rejected | F12: P1 | G12: 8 | H12: 4 | I12: =IF(H12="","",README!$C$6+(H12-1)*7) | J12: =IF(H12="","",README!$C$6+(H12-1)*7+4) | K12: Not Started | M12: =IF(K12="Done",1,IF(L12="",0,MIN(1,L12))) | P12: =IF(K12="Done",IF(O12="","Done",IF(J12="","Done",IF(O12<=J12,"On time","Late"))),IF(K12="Blocked","BLOCKED",IF(I12="","",IF(TODAY()>J12,"OVERDUE",IF(TODAY()>=I12,"Active","Upcoming")))))
A13: MB-T11 | B13: Platform | C13: SaaS | D13: RBAC + customer-facing audit log service | E13: Every mutating endpoint emits an audit event | F13: P0 | G13: 12 | H13: 4 | I13: =IF(H13="","",README!$C$6+(H13-1)*7) | J13: =IF(H13="","",README!$C$6+(H13-1)*7+4) | K13: Not Started | M13: =IF(K13="Done",1,IF(L13="",0,MIN(1,L13))) | P13: =IF(K13="Done",IF(O13="","Done",IF(J13="","Done",IF(O13<=J13,"On time","Late"))),IF(K13="Blocked","BLOCKED",IF(I13="","",IF(TODAY()>J13,"OVERDUE",IF(TODAY()>=I13,"Active","Upcoming")))))
A14: MB-T12 | B14: Platform | C14: SaaS | D14: Per-tenant rate limiting and quotas | E14: 429 with Retry-After; quota visible in admin | F14: P0 | G14: 8 | H14: 4 | I14: =IF(H14="","",README!$C$6+(H14-1)*7) | J14: =IF(H14="","",README!$C$6+(H14-1)*7+4) | K14: Not Started | M14: =IF(K14="Done",1,IF(L14="",0,MIN(1,L14))) | P14: =IF(K14="Done",IF(O14="","Done",IF(J14="","Done",IF(O14<=J14,"On time","Late"))),IF(K14="Blocked","BLOCKED",IF(I14="","",IF(TODAY()>J14,"OVERDUE",IF(TODAY()>=I14,"Active","Upcoming")))))
A15: MB-T13 | B15: Platform | C15: SaaS | D15: Dogfood: bill Meterbook's own customers with Meterbook (Stripe as payment provider) | E15: Own subscriptions invoiced by Meterbook | F15: P1 | G15: 10 | H15: 4 | I15: =IF(H15="","",README!$C$6+(H15-1)*7) | J15: =IF(H15="","",README!$C$6+(H15-1)*7+4) | K15: Not Started | M15: =IF(K15="Done",1,IF(L15="",0,MIN(1,L15))) | P15: =IF(K15="Done",IF(O15="","Done",IF(J15="","Done",IF(O15<=J15,"On time","Late"))),IF(K15="Blocked","BLOCKED",IF(I15="","",IF(TODAY()>J15,"OVERDUE",IF(TODAY()>=I15,"Active","Upcoming")))))
A16: MB-T14 | B16: Platform | C16: Observability | D16: OTel Collector, Prometheus, Grafana, Loki, Tempo; golden-signal dashboards | E16: Every service has RED dashboard and trace links | F16: P0 | G16: 12 | H16: 4 | I16: =IF(H16="","",README!$C$6+(H16-1)*7) | J16: =IF(H16="","",README!$C$6+(H16-1)*7+4) | K16: Not Started | M16: =IF(K16="Done",1,IF(L16="",0,MIN(1,L16))) | P16: =IF(K16="Done",IF(O16="","Done",IF(J16="","Done",IF(O16<=J16,"On time","Late"))),IF(K16="Blocked","BLOCKED",IF(I16="","",IF(TODAY()>J16,"OVERDUE",IF(TODAY()>=I16,"Active","Upcoming")))))
A17: MB-T15 | B17: Platform | C17: Ops | D17: Public status page, incident runbook template, on-call rotation doc | E17: Status page live; runbook template used by product services | F17: P2 | G17: 4 | H17: 4 | I17: =IF(H17="","",README!$C$6+(H17-1)*7) | J17: =IF(H17="","",README!$C$6+(H17-1)*7+4) | K17: Not Started | M17: =IF(K17="Done",1,IF(L17="",0,MIN(1,L17))) | P17: =IF(K17="Done",IF(O17="","Done",IF(J17="","Done",IF(O17<=J17,"On time","Late"))),IF(K17="Blocked","BLOCKED",IF(I17="","",IF(TODAY()>J17,"OVERDUE",IF(TODAY()>=I17,"Active","Upcoming")))))
A18: MB-T16 | B18: Product | C18: Design | D18: PRD + Google-style design doc (alternatives, trade-offs, capacity estimate) | E18: Doc reviewed; open questions closed | F18: P0 | G18: 10 | H18: 5 | I18: =IF(H18="","",README!$C$6+(H18-1)*7) | J18: =IF(H18="","",README!$C$6+(H18-1)*7+4) | K18: Not Started | M18: =IF(K18="Done",1,IF(L18="",0,MIN(1,L18))) | P18: =IF(K18="Done",IF(O18="","Done",IF(J18="","Done",IF(O18<=J18,"On time","Late"))),IF(K18="Blocked","BLOCKED",IF(I18="","",IF(TODAY()>J18,"OVERDUE",IF(TODAY()>=I18,"Active","Upcoming")))))
A19: MB-T17 | B19: Product | C19: Design | D19: Data model: accounts, ledger entries, invoices, money in minor units | E19: ERD + ADR for ledger immutability and isolation level | F19: P0 | G19: 8 | H19: 5 | I19: =IF(H19="","",README!$C$6+(H19-1)*7) | J19: =IF(H19="","",README!$C$6+(H19-1)*7+4) | K19: Not Started | M19: =IF(K19="Done",1,IF(L19="",0,MIN(1,L19))) | P19: =IF(K19="Done",IF(O19="","Done",IF(J19="","Done",IF(O19<=J19,"On time","Late"))),IF(K19="Blocked","BLOCKED",IF(I19="","",IF(TODAY()>J19,"OVERDUE",IF(TODAY()>=I19,"Active","Upcoming")))))
... A40: MB-T38 | B40: Product | C40: Launch | D40: Public benchmark + reliability report (README + blog) | E40: Report links Dashboard evidence | F40: P1 | G40: 6 | H40: 14 | I40: =IF(H40="","",README!$C$6+(H40-1)*7) | J40: =IF(H40="","",README!$C$6+(H40-1)*7+4) | K40: Not Started | M40: =IF(K40="Done",1,IF(L40="",0,MIN(1,L40))) | P40: =IF(K40="Done",IF(O40="","Done",IF(J40="","Done",IF(O40<=J40,"On time","Late"))),IF(K40="Blocked","BLOCKED",IF(I40="","",IF(TODAY()>J40,"OVERDUE",IF(TODAY()>=I40,"Active","Upcoming")))))

Sheet Test_Catalog
A1: Test Type | B1: Category | C1: Box | D1: What It Proves | E1: When It Runs | F1: Tools — Java | G1: Tools — Go | H1: Tools — Rust | I1: Tools — Python | J1: Pass Gate | K1: Evidence to Show
A2: Unit | B2: Functional | C2: White | D2: Each function/class behaves correctly in isolation | E2: Pre-commit + every PR | F2: JUnit 5, AssertJ, Mockito | G2: testing, testify | H2: cargo test | I2: pytest | J2: 100% pass; coverage targets met | K2: CI run + coverage report
A3: Integration | B3: Functional | C3: Grey | D3: Components work with real DB/Kafka/Redis | E3: Every PR | F3: Testcontainers, Spring Boot Test | G3: testcontainers-go | H3: testcontainers-rs | I3: testcontainers-python | J3: 100% pass | K3: CI run
A4: Component / Service | B4: Functional | C4: Grey | D4: One service works end-to-end with dependencies stubbed | E4: Every PR | F4: WireMock, RestAssured | G4: httptest, gomock | H4: wiremock-rs | I4: respx, pytest-httpx | J4: 100% pass | K4: CI run
A5: Contract (consumer-driven) | B5: Functional | C5: Black | D5: API producer and consumers agree; no breaking changes | E5: Every PR | F5: Pact JVM | G5: pact-go | H5: pact_consumer | I5: pact-python | J5: All pacts verified; buf/oasdiff breaking check passes | K5: Pact Broker matrix
A6: API (schema-based) | B6: Functional | C6: Black | D6: Every endpoint honours its OpenAPI spec | E6: Every PR | F6: RestAssured | G6: Schemathesis (CLI) | H6: Schemathesis (CLI) | I6: Schemathesis | J6: 0 spec violations, 0 5xx | K6: Schemathesis report
A7: Functional | B7: Functional | C7: Black | D7: Features meet requirements from the user's view | E7: Every PR / nightly | F7: RestAssured, Cucumber | G7: godog | H7: cucumber-rs | I7: pytest-bdd | J7: 100% pass on P0 cases | K7: Test report
A8: End-to-End (E2E) | B8: Functional | C8: Black | D8: Full user journeys across UI + APIs + workers | E8: Nightly + pre-release | F8: Playwright | G8: Playwright | H8: Playwright | I8: Playwright | J8: 100% pass on critical journeys | K8: Playwright trace/video
A9: Smoke | B9: Functional | C9: Black | D9: Deployment is alive: health checks + 1 golden path | E9: After every deploy | F9: k6 / curl scripts | G9: k6 | H9: k6 | I9: k6 | J9: Pass within 2 min or auto-rollback | K9: Deploy log
A10: Sanity | B10: Functional | C10: Black | D10: A specific fix works before full regression | E10: Per hotfix | F10: Targeted suite | G10: Targeted suite | H10: Targeted suite | I10: Targeted suite | J10: Pass | K10: CI run
A11: Regression | B11: Functional | C11: Black | D11: Old features still work after changes | E11: Nightly + pre-release | F11: Full suite / golden files | G11: Full suite / golden files | H11: insta snapshots | I11: syrupy snapshots | J11: 0 new failures | K11: Nightly report
A12: User Acceptance (UAT) | B12: Functional | C12: Black | D12: A target persona can do the job (e.g. finance closes month) | E12: Pre-release | F12: Scripted walkthrough | G12: Scripted walkthrough | H12: Scripted walkthrough | I12: Scripted walkthrough | J12: Persona signs off | K12: Recorded demo
... A48: ML / LLM quality evaluation | B48: Functional | C48: Black | D48: RAG retrieval and answer quality; guardrail accuracy | E48: Every PR touching prompts/retrieval | F48: n/a | G48: n/a | H48: n/a | I48: Ragas, DeepEval, promptfoo | J48: Scores >= targets; no drop > 2% | K48: Eval report

Sheet Test_Cases
A1: Test ID | B1: Track | C1: Test Type | D1: Box | E1: Component | F1: Scenario | G1: Expected Result | H1: Tool | I1: Priority | J1: Automated (Y/N) | K1: Status | L1: Last Run | M1: Actual Result | N1: Defect ID | O1: Evidence Link
A2: EX-TC-001 | B2: EXAMPLE | C2: Idempotency | D2: =IFERROR(INDEX(Test_Catalog!$C$2:$C$48,MATCH(C2,Test_Catalog!$A$2:$A$48,0)),"") | E2: Payments API | F2: Example: same key POSTed twice | G2: One ledger entry | H2: Custom harness | I2: P0 | J2: Y | K2: Pass | L2: 46336 | M2: 1 entry, identical 201 responses | O2: https://github.com/you/repo/actions/runs/123
A3: TC-PLT-001 | B3: Platform | C3: Integration | D3: =IFERROR(INDEX(Test_Catalog!$C$2:$C$48,MATCH(C3,Test_Catalog!$A$2:$A$48,0)),"") | E3: Identity | F3: OIDC login with test Keycloak realm | G3: Token issued; claims include tenant_id and roles | H3: Playwright + Testcontainers | I3: P0 | J3: Y | K3: Not Run
A4: TC-PLT-002 | B4: Platform | C4: AuthN / AuthZ & tenant isolation | D4: =IFERROR(INDEX(Test_Catalog!$C$2:$C$48,MATCH(C4,Test_Catalog!$A$2:$A$48,0)),"") | E4: Tenancy | F4: Tenant A requests Tenant B resource by ID | G4: 403/404; RLS blocks query; audit event logged | H4: Custom suite | I4: P0 | J4: Y | K4: Not Run
A5: TC-PLT-003 | B5: Platform | C5: AuthN / AuthZ & tenant isolation | D5: =IFERROR(INDEX(Test_Catalog!$C$2:$C$48,MATCH(C5,Test_Catalog!$A$2:$A$48,0)),"") | E5: API keys | F5: Use a revoked API key | G5: 401 within 60 s of revocation | H5: Custom suite | I5: P0 | J5: Y | K5: Not Run
A6: TC-PLT-004 | B6: Platform | C6: Functional | D6: =IFERROR(INDEX(Test_Catalog!$C$2:$C$48,MATCH(C6,Test_Catalog!$A$2:$A$48,0)),"") | E6: Rate limiting | F6: Exceed tenant quota | G6: 429 with Retry-After; other tenants unaffected | H6: k6 | I6: P0 | J6: Y | K6: Not Run
A7: TC-PLT-005 | B7: Platform | C7: SAST | D7: =IFERROR(INDEX(Test_Catalog!$C$2:$C$48,MATCH(C7,Test_Catalog!$A$2:$A$48,0)),"") | E7: CI | F7: Semgrep + CodeQL on every PR | G7: 0 high/critical findings | H7: Semgrep, CodeQL | I7: P0 | J7: Y | K7: Not Run
A8: TC-PLT-006 | B8: Platform | C8: SCA / Dependency & image scan | D8: =IFERROR(INDEX(Test_Catalog!$C$2:$C$48,MATCH(C8,Test_Catalog!$A$2:$A$48,0)),"") | E8: CI | F8: Trivy scan of all images | G8: 0 critical CVEs | H8: Trivy | I8: P0 | J8: Y | K8: Not Run
A9: TC-PLT-007 | B9: Platform | C9: Secrets scanning | D9: =IFERROR(INDEX(Test_Catalog!$C$2:$C$48,MATCH(C9,Test_Catalog!$A$2:$A$48,0)),"") | E9: CI | F9: gitleaks over full history | G9: 0 findings | H9: gitleaks | I9: P0 | J9: Y | K9: Pass | L9: 46318 | M9: 0 findings across full history | O9: https://github.com/mhrj7/meterbook/actions/runs/39905115436
A10: TC-PLT-008 | B10: Platform | C10: DAST | D10: =IFERROR(INDEX(Test_Catalog!$C$2:$C$48,MATCH(C10,Test_Catalog!$A$2:$A$48,0)),"") | E10: Public API | F10: ZAP baseline scan on staging | G10: 0 high alerts | H10: OWASP ZAP | I10: P1 | J10: Y | K10: Not Run
A11: TC-PLT-009 | B11: Platform | C11: Smoke | D11: =IFERROR(INDEX(Test_Catalog!$C$2:$C$48,MATCH(C11,Test_Catalog!$A$2:$A$48,0)),"") | E11: Deploy | F11: Post-deploy health + golden path | G11: All /healthz 200 within 2 min | H11: k6 | I11: P0 | J11: Y | K11: Not Run
A12: TC-PLT-010 | B12: Platform | C12: Backup & restore | D12: =IFERROR(INDEX(Test_Catalog!$C$2:$C$48,MATCH(C12,Test_Catalog!$A$2:$A$48,0)),"") | E12: RDS | F12: Restore latest snapshot to a fresh env | G12: Data checksum matches; RPO <= 5 min | H12: Runbook | I12: P0 | J12: Y | K12: Not Run
A13: TC-PLT-011 | B13: Platform | C13: Compliance / Audit | D13: =IFERROR(INDEX(Test_Catalog!$C$2:$C$48,MATCH(C13,Test_Catalog!$A$2:$A$48,0)),"") | E13: Audit log | F13: Every mutating endpoint emits audit event | G13: 100% of endpoints covered | H13: Custom suite | I13: P1 | J13: Y | K13: Not Run
A14: TC-PLT-012 | B14: Platform | C14: Deployment / Rollback | D14: =IFERROR(INDEX(Test_Catalog!$C$2:$C$48,MATCH(C14,Test_Catalog!$A$2:$A$48,0)),"") | E14: ArgoCD | F14: Deploy a build that fails health checks | G14: Auto-rollback; no user-visible errors | H14: Argo Rollouts | I14: P0 | J14: Y | K14: Not Run
A15: TC-PLT-013 | B15: Platform | C15: Static analysis / Lint | D15: =IFERROR(INDEX(Test_Catalog!$C$2:$C$48,MATCH(C15,Test_Catalog!$A$2:$A$48,0)),"") | E15: CI | F15: golangci-lint, clippy, SpotBugs, ruff on all repos | G15: 0 errors; PR blocked otherwise | H15: Linters in CI | I15: P0 | J15: Y | K15: Not Run
A16: TC-PLT-014 | B16: Platform | C16: Statement / Branch coverage | D16: =IFERROR(INDEX(Test_Catalog!$C$2:$C$48,MATCH(C16,Test_Catalog!$A$2:$A$48,0)),"") | E16: CI | F16: Coverage gate on every PR | G16: PR blocked below Coverage sheet targets | H16: Codecov | I16: P0 | J16: Y | K16: Not Run
A17: TC-PLT-015 | B17: Platform | C17: Sanity | D17: =IFERROR(INDEX(Test_Catalog!$C$2:$C$48,MATCH(C17,Test_Catalog!$A$2:$A$48,0)),"") | E17: Hotfix | F17: Targeted suite for a hotfix before full regression | G17: Passes in < 5 min | H17: CI targeted job | I17: P1 | J17: Y | K17: Not Run
A18: TC-PLT-016 | B18: Platform | C18: Failover / Disaster recovery | D18: =IFERROR(INDEX(Test_Catalog!$C$2:$C$48,MATCH(C18,Test_Catalog!$A$2:$A$48,0)),"") | E18: RDS | F18: Multi-AZ failover drill under load | G18: RTO <= 2 min; no committed data lost | H18: Runbook drill | I18: P0 | J18: Y | K18: Not Run
A19: TC-PLT-017 | B19: Platform | C19: Chaos engineering | D19: =IFERROR(INDEX(Test_Catalog!$C$2:$C$48,MATCH(C19,Test_Catalog!$A$2:$A$48,0)),"") | E19: Game day | F19: Run every Chaos_Resilience experiment for P0 | G19: All PASS | H19: Chaos Mesh | I19: P1 | J19: Y | K19: Not Run
A20: TC-PLT-018 | B20: Platform | C20: Capacity planning | D20: =IFERROR(INDEX(Test_Catalog!$C$2:$C$48,MATCH(C20,Test_Catalog!$A$2:$A$48,0)),"") | E20: Platform | F20: Measure CPU/mem/cost per 1,000 tenants | G20: Capacity model in design doc | H20: k6 + Cost Explorer | I20: P2 | J20: Y | K20: Not Run
A21: TC-PLT-019 | B21: Platform | C21: Penetration test (checklist) | D21: =IFERROR(INDEX(Test_Catalog!$C$2:$C$48,MATCH(C21,Test_Catalog!$A$2:$A$48,0)),"") | E21: Public API | F21: OWASP ASVS L2 + API Top 10 checklist | G21: No open high findings | H21: Burp Suite | I21: P0 | J21: Y | K21: Not Run
... A47: TC-MB-026 | B47: Product | C47: Volume | D47: =IFERROR(INDEX(Test_Catalog!$C$2:$C$48,MATCH(C47,Test_Catalog!$A$2:$A$48,0)),"") | E47: Invoicing | F47: Execute run LR-MB-06 | G47: 100k invoices in <= 15 min | H47: Custom generator | I47: P1 | J47: Y | K47: Not Run

Sheet Metrics_SLOs
A1: Metric ID | B1: Track | C1: Category | D1: Metric | E1: Comparator | F1: Target | G1: Unit | H1: Measured (input) | I1: Result | J1: Measured By | K1: Run Ref | L1: Date | M1: Evidence Link | N1: Notes
A2: EX-M-001 | B2: EXAMPLE | C2: Latency | D2: Example: write API p99 | E2: <= | F2: 50 | G2: ms | H2: 38 | I2: =IF(H2="","PENDING",IF(E2="<=",IF(H2<=F2,"PASS","FAIL"),IF(H2>=F2,"PASS","FAIL"))) | J2: Gatling | K2: EX-LR-001 | L2: 46338 | M2: https://grafana.example/d/abc
A3: M-PLT-01 | B3: Platform | C3: Availability | D3: Control-plane availability (30-day) | E3: >= | F3: 0.999 | G3: % | I3: =IF(H3="","PENDING",IF(E3="<=",IF(H3<=F3,"PASS","FAIL"),IF(H3>=F3,"PASS","FAIL"))) | J3: Prometheus SLO
A4: M-PLT-02 | B4: Platform | C4: Latency | D4: Login / token issue p99 | E4: <= | F4: 300 | G4: ms | I4: =IF(H4="","PENDING",IF(E4="<=",IF(H4<=F4,"PASS","FAIL"),IF(H4>=F4,"PASS","FAIL"))) | J4: k6
A5: M-PLT-03 | B5: Platform | C5: Delivery (DORA) | D5: CI pipeline duration | E5: <= | F5: 10 | G5: min | H5: 3.3 | I5: =IF(H5="","PENDING",IF(E5="<=",IF(H5<=F5,"PASS","FAIL"),IF(H5>=F5,"PASS","FAIL"))) | J5: GitHub Actions | K5: 39905115436 | L5: 46318 | M5: https://github.com/mhrj7/meterbook/actions/runs/39905115436 | N5: Wall clock from run created to last job completed, PR #3.
A6: M-PLT-04 | B6: Platform | C6: Delivery (DORA) | D6: Deployment frequency | E6: >= | F6: 5 | G6: deploys/week | I6: =IF(H6="","PENDING",IF(E6="<=",IF(H6<=F6,"PASS","FAIL"),IF(H6>=F6,"PASS","FAIL"))) | J6: ArgoCD history
A7: M-PLT-05 | B7: Platform | C7: Delivery (DORA) | D7: Change failure rate | E7: <= | F7: 0.15 | G7: % | I7: =IF(H7="","PENDING",IF(E7="<=",IF(H7<=F7,"PASS","FAIL"),IF(H7>=F7,"PASS","FAIL"))) | J7: Incident log
A8: M-PLT-06 | B8: Platform | C8: Delivery (DORA) | D8: Mean time to restore (MTTR) | E8: <= | F8: 30 | G8: min | I8: =IF(H8="","PENDING",IF(E8="<=",IF(H8<=F8,"PASS","FAIL"),IF(H8>=F8,"PASS","FAIL"))) | J8: Incident log
A9: M-PLT-07 | B9: Platform | C9: Security | D9: Critical CVEs in deployed images | E9: <= | F9: 0 | G9: count | I9: =IF(H9="","PENDING",IF(E9="<=",IF(H9<=F9,"PASS","FAIL"),IF(H9>=F9,"PASS","FAIL"))) | J9: Trivy
A10: M-PLT-08 | B10: Platform | C10: Recovery | D10: RPO (data loss window) | E10: <= | F10: 5 | G10: min | I10: =IF(H10="","PENDING",IF(E10="<=",IF(H10<=F10,"PASS","FAIL"),IF(H10>=F10,"PASS","FAIL"))) | J10: Restore drill
A11: M-PLT-09 | B11: Platform | C11: Recovery | D11: RTO (time to restore) | E11: <= | F11: 30 | G11: min | I11: =IF(H11="","PENDING",IF(E11="<=",IF(H11<=F11,"PASS","FAIL"),IF(H11>=F11,"PASS","FAIL"))) | J11: Restore drill
A12: M-MB-01 | B12: Product | C12: Throughput | D12: Usage-event ingestion | E12: >= | F12: 10000 | G12: events/s | I12: =IF(H12="","PENDING",IF(E12="<=",IF(H12<=F12,"PASS","FAIL"),IF(H12>=F12,"PASS","FAIL"))) | J12: Gatling
A13: M-MB-02 | B13: Product | C13: Latency | D13: Write API p95 | E13: <= | F13: 25 | G13: ms | I13: =IF(H13="","PENDING",IF(E13="<=",IF(H13<=F13,"PASS","FAIL"),IF(H13>=F13,"PASS","FAIL"))) | J13: Gatling
A14: M-MB-03 | B14: Product | C14: Latency | D14: Write API p99 | E14: <= | F14: 50 | G14: ms | I14: =IF(H14="","PENDING",IF(E14="<=",IF(H14<=F14,"PASS","FAIL"),IF(H14>=F14,"PASS","FAIL"))) | J14: Gatling
A15: M-MB-04 | B15: Product | C15: Errors | D15: Error rate at peak load | E15: <= | F15: 0.001 | G15: % | I15: =IF(H15="","PENDING",IF(E15="<=",IF(H15<=F15,"PASS","FAIL"),IF(H15>=F15,"PASS","FAIL"))) | J15: Gatling
A16: M-MB-05 | B16: Product | C16: Correctness | D16: Ledger drift after chaos (sum debits - credits) | E16: <= | F16: 0 | G16: minor units | I16: =IF(H16="","PENDING",IF(E16="<=",IF(H16<=F16,"PASS","FAIL"),IF(H16>=F16,"PASS","FAIL"))) | J16: Invariant checker
A17: M-MB-06 | B17: Product | C17: Correctness | D17: Duplicate charges under retries | E17: <= | F17: 0 | G17: count | I17: =IF(H17="","PENDING",IF(E17="<=",IF(H17<=F17,"PASS","FAIL"),IF(H17>=F17,"PASS","FAIL"))) | J17: Idempotency suite
... A23: M-MB-12 | B23: Product | C23: Availability | D23: API availability (30-day) | E23: >= | F23: 0.9995 | G23: % | I23: =IF(H23="","PENDING",IF(E23="<=",IF(H23<=F23,"PASS","FAIL"),IF(H23>=F23,"PASS","FAIL"))) | J23: Prometheus SLO

Sheet Load_Stress_Runs
A1: Run ID | B1: Track | C1: Test Type | D1: Scenario | E1: Tool | F1: Environment | G1: Duration (min) | H1: Target Load | I1: Achieved Load | J1: p50 (ms) | K1: p95 (ms) | L1: p99 (ms) | M1: p99.9 (ms) | N1: Error Rate | O1: Max CPU % | P1: Max Memory (GB) | Q1: SLO p99 (ms) | R1: SLO Max Error | S1: Attainment | T1: Result | U1: Date | V1: Breaking Point / Observations | W1: Evidence Link
A2: EX-LR-001 | B2: EXAMPLE | C2: Load | D2: Example: ingestion at 10k events/s | E2: Gatling | F2: staging | G2: 30 | H2: 10000 | I2: 10450 | J2: 8 | K2: 21 | L2: 38 | M2: 95 | N2: 0.0003 | O2: 0.68 | P2: 3.1 | Q2: 50 | R2: 0.001 | S2: =IF(OR(H2="",I2="",H2=0),"",I2/H2) | T2: =IF(I2="","NOT RUN",IF(AND(I2>=H2,OR(Q2=0,L2<=Q2),N2<=R2),"PASS","FAIL")) | U2: 46338 | V2: Kafka consumer lag peaked at 1.2 s | W2: https://grafana.example/d/abc
A3: LR-PLT-01 | B3: Platform | C3: Load | D3: Auth: 500 logins/s for 15 min | E3: k6 | F3: staging: 3 x m6i.large | G3: 15 | H3: 500 | Q3: 300 | R3: 0.001 | S3: =IF(OR(H3="",I3="",H3=0),"",I3/H3) | T3: =IF(I3="","NOT RUN",IF(AND(I3>=H3,OR(Q3=0,L3<=Q3),N3<=R3),"PASS","FAIL"))
A4: LR-PLT-02 | B4: Platform | C4: Spike | D4: Auth: 0 -> 2,000 logins/s in 10 s | E4: k6 | F4: staging | G4: 5 | H4: 2000 | Q4: 800 | R4: 0.01 | S4: =IF(OR(H4="",I4="",H4=0),"",I4/H4) | T4: =IF(I4="","NOT RUN",IF(AND(I4>=H4,OR(Q4=0,L4<=Q4),N4<=R4),"PASS","FAIL"))
A5: LR-MB-01 | B5: Product | C5: Load | D5: Usage ingestion at 10k events/s | E5: Gatling | F5: staging: 6 x m6i.xlarge, MSK 3 brokers | G5: 30 | H5: 10000 | Q5: 50 | R5: 0.001 | S5: =IF(OR(H5="",I5="",H5=0),"",I5/H5) | T5: =IF(I5="","NOT RUN",IF(AND(I5>=H5,OR(Q5=0,L5<=Q5),N5<=R5),"PASS","FAIL"))
A6: LR-MB-02 | B6: Product | C6: Stress / Breakpoint | D6: Ramp ingestion until SLO breach (target = expected peak x3) | E6: Gatling | F6: staging | G6: 30 | H6: 30000 | Q6: 200 | R6: 0.01 | S6: =IF(OR(H6="",I6="",H6=0),"",I6/H6) | T6: =IF(I6="","NOT RUN",IF(AND(I6>=H6,OR(Q6=0,L6<=Q6),N6<=R6),"PASS","FAIL"))
A7: LR-MB-03 | B7: Product | C7: Spike | D7: Invoice API 0 -> 5k RPS in 10 s | E7: Gatling | F7: staging | G7: 5 | H7: 5000 | Q7: 150 | R7: 0.01 | S7: =IF(OR(H7="",I7="",H7=0),"",I7/H7) | T7: =IF(I7="","NOT RUN",IF(AND(I7>=H7,OR(Q7=0,L7<=Q7),N7<=R7),"PASS","FAIL"))
A8: LR-MB-04 | B8: Product | C8: Soak / Endurance | D8: 60% peak for 8 h | E8: Gatling + JFR | F8: staging | G8: 480 | H8: 6000 | Q8: 50 | R8: 0.001 | S8: =IF(OR(H8="",I8="",H8=0),"",I8/H8) | T8: =IF(I8="","NOT RUN",IF(AND(I8>=H8,OR(Q8=0,L8<=Q8),N8<=R8),"PASS","FAIL"))
A9: LR-MB-05 | B9: Product | C9: Scalability | D9: Double app nodes 6 -> 12; expect >= 1.7x throughput | E9: Gatling | F9: staging | G9: 30 | H9: 17000 | Q9: 50 | R9: 0.001 | S9: =IF(OR(H9="",I9="",H9=0),"",I9/H9) | T9: =IF(I9="","NOT RUN",IF(AND(I9>=H9,OR(Q9=0,L9<=Q9),N9<=R9),"PASS","FAIL"))
A10: LR-MB-06 | B10: Product | C10: Volume | D10: Invoice run on 100k customers / 50M usage rows | E10: Custom generator | F10: staging | G10: 15 | H10: 100000 | Q10: 0 | R10: 0 | S10: =IF(OR(H10="",I10="",H10=0),"",I10/H10) | T10: =IF(I10="","NOT RUN",IF(AND(I10>=H10,OR(Q10=0,L10<=Q10),N10<=R10),"PASS","FAIL"))

Sheet Chaos_Resilience
A1: Experiment ID | B1: Track | C1: Fault Injected | D1: Steady-State Hypothesis | E1: Injection Method | F1: Blast Radius | G1: Expected Behaviour | H1: Observed Behaviour (input) | I1: Recovery Time (s) | J1: Target RTO (s) | K1: Data Loss? (Y/N) | L1: Date | M1: Result | N1: Evidence Link
A2: EX-CH-001 | B2: EXAMPLE | C2: Kafka broker loss | D2: Zero lost events | E2: PodChaos | F2: Ingestion | G2: Producer retries | H2: Lag spike 4 s; all events delivered | I2: 12 | J2: 30 | K2: N | L2: 46340 | M2: =IF(I2="","NOT RUN",IF(AND(I2<=J2,K2="N"),"PASS","FAIL")) | N2: https://github.com/you/repo/blob/main/chaos/kafka.md
A3: CH-PLT-01 | B3: Platform | C3: Primary DB failover | D3: Control plane serves logins with < 1% errors | E3: RDS reboot with failover | F3: Control plane | G3: Multi-AZ failover; connection pool reconnects | J3: 120 | M3: =IF(I3="","NOT RUN",IF(AND(I3<=J3,K3="N"),"PASS","FAIL"))
A4: CH-PLT-02 | B4: Platform | C4: Identity provider down | D4: Existing sessions keep working | E4: Scale Keycloak to 0 | F4: Login only | G4: Cached JWKS; new logins fail with clear error | J4: 0 | M4: =IF(I4="","NOT RUN",IF(AND(I4<=J4,K4="N"),"PASS","FAIL"))
A5: CH-MB-01 | B5: Product | C5: Kafka broker loss | D5: Usage ingestion continues; zero lost events | E5: Chaos Mesh PodChaos on 1 of 3 brokers | F5: Ingestion | G5: Producer retries; ISR keeps writes durable | J5: 30 | M5: =IF(I5="","NOT RUN",IF(AND(I5<=J5,K5="N"),"PASS","FAIL"))
A6: CH-MB-02 | B6: Product | C6: App pod kill mid-transaction | D6: Ledger stays balanced | E6: PodChaos kill every 30 s for 10 min | F6: Ledger service | G6: Txn rolls back or commits atomically; outbox replays | J6: 10 | M6: =IF(I6="","NOT RUN",IF(AND(I6<=J6,K6="N"),"PASS","FAIL"))
A7: CH-MB-03 | B7: Product | C7: Postgres latency 500 ms | D7: API p99 degrades but no errors > 1% | E7: Toxiproxy latency | F7: Ledger DB | G7: Timeouts + breaker; idempotent retries | J7: 60 | M7: =IF(I7="","NOT RUN",IF(AND(I7<=J7,K7="N"),"PASS","FAIL"))
A8: CH-MB-04 | B8: Product | C8: PSP (Stripe) outage | D8: Payments queued, retried later; no double charge | E8: Toxiproxy 100% 503 | F8: Payment adapter | G8: Temporal retries with backoff | J8: 300 | M8: =IF(I8="","NOT RUN",IF(AND(I8<=J8,K8="N"),"PASS","FAIL"))
A9: CH-MB-05 | B9: Product | C9: Redis loss (idempotency store) | D9: No duplicate charges | E9: Delete Redis pod | F9: Idempotency | G9: Fallback to Postgres idempotency table | J9: 30 | M9: =IF(I9="","NOT RUN",IF(AND(I9<=J9,K9="N"),"PASS","FAIL"))

Sheet Coverage
A1: Track | B1: Module | C1: Language | D1: Tool | E1: Line % (input) | F1: Branch % (input) | G1: Mutation % (input) | H1: Target Line % | I1: Target Branch % | J1: Target Mutation % | K1: Result | L1: Date | M1: Evidence Link
A2: EXAMPLE | B2: ledger | C2: Java | D2: JaCoCo + PIT | E2: 0.93 | F2: 0.88 | G2: 0.79 | H2: 0.9 | I2: 0.85 | J2: 0.75 | K2: =IF(OR(E2="",F2="",G2=""),"PENDING",IF(AND(E2>=H2,F2>=I2,G2>=J2),"PASS","FAIL")) | L2: 46346 | M2: https://app.codecov.io/gh/you/repo
A3: Platform | B3: identity | C3: Java | D3: JaCoCo + PIT | H3: 0.9 | I3: 0.85 | J3: 0.75 | K3: =IF(OR(E3="",F3="",G3=""),"PENDING",IF(AND(E3>=H3,F3>=I3,G3>=J3),"PASS","FAIL"))
A4: Platform | B4: tenancy | C4: Java | D4: JaCoCo + PIT | H4: 0.9 | I4: 0.85 | J4: 0.75 | K4: =IF(OR(E4="",F4="",G4=""),"PENDING",IF(AND(E4>=H4,F4>=I4,G4>=J4),"PASS","FAIL"))
A5: Product | B5: ledger | C5: Java | D5: JaCoCo + PIT | H5: 0.9 | I5: 0.85 | J5: 0.75 | K5: =IF(OR(E5="",F5="",G5=""),"PENDING",IF(AND(E5>=H5,F5>=I5,G5>=J5),"PASS","FAIL"))
A6: Product | B6: pricing | C6: Java | D6: JaCoCo + PIT | H6: 0.9 | I6: 0.85 | J6: 0.75 | K6: =IF(OR(E6="",F6="",G6=""),"PENDING",IF(AND(E6>=H6,F6>=I6,G6>=J6),"PASS","FAIL"))
A7: Product | B7: invoicing | C7: Java | D7: JaCoCo + PIT | H7: 0.9 | I7: 0.85 | J7: 0.75 | K7: =IF(OR(E7="",F7="",G7=""),"PENDING",IF(AND(E7>=H7,F7>=I7,G7>=J7),"PASS","FAIL"))
A8: Product | B8: webhooks | C8: Java | D8: JaCoCo + PIT | H8: 0.9 | I8: 0.85 | J8: 0.75 | K8: =IF(OR(E8="",F8="",G8=""),"PENDING",IF(AND(E8>=H8,F8>=I8,G8>=J8),"PASS","FAIL"))

Sheet Defects
A1: Defect ID | B1: Track | C1: Title | D1: Severity | E1: Found By (Test ID) | F1: Status | G1: Opened | H1: Closed | I1: Days Open | J1: Root Cause | K1: Fix PR | L1: Regression Test Added (Y/N)
A2: EX-D-001 | B2: EXAMPLE | C2: Duplicate ledger entry when two retries race | D2: S1-Critical | E2: TC-MB-005 | F2: Closed | G2: 46336 | H2: 46337 | I2: =IF(G2="","",IF(H2="",TODAY()-G2,H2-G2)) | J2: Idempotency check and insert not in one transaction | K2: https://github.com/you/repo/pull/57 | L2: Y
I3: =IF(G3="","",IF(H3="",TODAY()-G3,H3-G3))
I4: =IF(G4="","",IF(H4="",TODAY()-G4,H4-G4))
I5: =IF(G5="","",IF(H5="",TODAY()-G5,H5-G5))
I6: =IF(G6="","",IF(H6="",TODAY()-G6,H6-G6))
I7: =IF(G7="","",IF(H7="",TODAY()-G7,H7-G7))
I8: =IF(G8="","",IF(H8="",TODAY()-G8,H8-G8))
I9: =IF(G9="","",IF(H9="",TODAY()-G9,H9-G9))
I10: =IF(G10="","",IF(H10="",TODAY()-G10,H10-G10))
I11: =IF(G11="","",IF(H11="",TODAY()-G11,H11-G11))
I12: =IF(G12="","",IF(H12="",TODAY()-G12,H12-G12))
I13: =IF(G13="","",IF(H13="",TODAY()-G13,H13-G13))
I14: =IF(G14="","",IF(H14="",TODAY()-G14,H14-G14))
... I101: =IF(G101="","",IF(H101="",TODAY()-G101,H101-G101))

Sheet Weekly_Log
A1: Week # | B1: Week Start | C1: Focus Track | D1: Planned Tasks | E1: Tasks Done | F1: Planned Hours | G1: Hours Logged (input) | H1: Wins / Demo | I1: Blockers | J1: Learnings | K1: Evidence Link
A2: 1 | B2: =README!$C$6+(A2-1)*7 | C2: Platform | D2: =COUNTIF(Plan!$H$2:$H$600,A2) | E2: =COUNTIFS(Plan!$H$2:$H$600,A2,Plan!$K$2:$K$600,"Done") | F2: =SUMIF(Plan!$H$2:$H$600,A2,Plan!$G$2:$G$600)
A3: 2 | B3: =README!$C$6+(A3-1)*7 | C3: Platform | D3: =COUNTIF(Plan!$H$2:$H$600,A3) | E3: =COUNTIFS(Plan!$H$2:$H$600,A3,Plan!$K$2:$K$600,"Done") | F3: =SUMIF(Plan!$H$2:$H$600,A3,Plan!$G$2:$G$600)
A4: 3 | B4: =README!$C$6+(A4-1)*7 | C4: Platform | D4: =COUNTIF(Plan!$H$2:$H$600,A4) | E4: =COUNTIFS(Plan!$H$2:$H$600,A4,Plan!$K$2:$K$600,"Done") | F4: =SUMIF(Plan!$H$2:$H$600,A4,Plan!$G$2:$G$600)
A5: 4 | B5: =README!$C$6+(A5-1)*7 | C5: Platform | D5: =COUNTIF(Plan!$H$2:$H$600,A5) | E5: =COUNTIFS(Plan!$H$2:$H$600,A5,Plan!$K$2:$K$600,"Done") | F5: =SUMIF(Plan!$H$2:$H$600,A5,Plan!$G$2:$G$600)
A6: 5 | B6: =README!$C$6+(A6-1)*7 | C6: Product | D6: =COUNTIF(Plan!$H$2:$H$600,A6) | E6: =COUNTIFS(Plan!$H$2:$H$600,A6,Plan!$K$2:$K$600,"Done") | F6: =SUMIF(Plan!$H$2:$H$600,A6,Plan!$G$2:$G$600)
A7: 6 | B7: =README!$C$6+(A7-1)*7 | C7: Product | D7: =COUNTIF(Plan!$H$2:$H$600,A7) | E7: =COUNTIFS(Plan!$H$2:$H$600,A7,Plan!$K$2:$K$600,"Done") | F7: =SUMIF(Plan!$H$2:$H$600,A7,Plan!$G$2:$G$600)
A8: 7 | B8: =README!$C$6+(A8-1)*7 | C8: Product | D8: =COUNTIF(Plan!$H$2:$H$600,A8) | E8: =COUNTIFS(Plan!$H$2:$H$600,A8,Plan!$K$2:$K$600,"Done") | F8: =SUMIF(Plan!$H$2:$H$600,A8,Plan!$G$2:$G$600)
A9: 8 | B9: =README!$C$6+(A9-1)*7 | C9: Product | D9: =COUNTIF(Plan!$H$2:$H$600,A9) | E9: =COUNTIFS(Plan!$H$2:$H$600,A9,Plan!$K$2:$K$600,"Done") | F9: =SUMIF(Plan!$H$2:$H$600,A9,Plan!$G$2:$G$600)
A10: 9 | B10: =README!$C$6+(A10-1)*7 | C10: Product | D10: =COUNTIF(Plan!$H$2:$H$600,A10) | E10: =COUNTIFS(Plan!$H$2:$H$600,A10,Plan!$K$2:$K$600,"Done") | F10: =SUMIF(Plan!$H$2:$H$600,A10,Plan!$G$2:$G$600)
A11: 10 | B11: =README!$C$6+(A11-1)*7 | C11: Product | D11: =COUNTIF(Plan!$H$2:$H$600,A11) | E11: =COUNTIFS(Plan!$H$2:$H$600,A11,Plan!$K$2:$K$600,"Done") | F11: =SUMIF(Plan!$H$2:$H$600,A11,Plan!$G$2:$G$600)
A12: 11 | B12: =README!$C$6+(A12-1)*7 | C12: Product | D12: =COUNTIF(Plan!$H$2:$H$600,A12) | E12: =COUNTIFS(Plan!$H$2:$H$600,A12,Plan!$K$2:$K$600,"Done") | F12: =SUMIF(Plan!$H$2:$H$600,A12,Plan!$G$2:$G$600)
A13: 12 | B13: =README!$C$6+(A13-1)*7 | C13: Product | D13: =COUNTIF(Plan!$H$2:$H$600,A13) | E13: =COUNTIFS(Plan!$H$2:$H$600,A13,Plan!$K$2:$K$600,"Done") | F13: =SUMIF(Plan!$H$2:$H$600,A13,Plan!$G$2:$G$600)
... A15: 14 | B15: =README!$C$6+(A15-1)*7 | C15: Product | D15: =COUNTIF(Plan!$H$2:$H$600,A15) | E15: =COUNTIFS(Plan!$H$2:$H$600,A15,Plan!$K$2:$K$600,"Done") | F15: =SUMIF(Plan!$H$2:$H$600,A15,Plan!$G$2:$G$600)
